Workbook

Sheet Cover
A5: * Design * Install * Maintain * Tree Care * Irrigation * Landscape Lighting * Water Features * Stonework *
A6: 1814 W. Howard Lane s Austin TX 78728 s 512.266.3167 phone s 512.266.7613 fax
A8: ='Controller A(2)'!G6 -> Amazon | J8: Date: | K8: 9.20.2021
A9: ='Controller A(2)'!G7 -> 2956 Main Street | J9: Job #: | K9: ='Controller A(2)'!G9 -> 0
A10: ='Controller A(2)'!G8 -> Buda, Texas
A12: To whom it may concern:
B14: The irrigation system at the property mentioned above was inspected on | I14: ='Controller A(2)'!G10 -> 9.25.2024
B16: Please review the totals below for all Critical and Non-Critical repairs:
B18: TOTAL for CRITICAL REPAIRS: (This DOES NOT include sales tax) | K18: 14451.31
B20: TOTAL for NON-CRITICAL REPAIRS: (This DOES NOT include sales tax)
B22: TOTAL for CRITICAL AND NON-CRITICAL REPAIRS: (This DOES NOT include sales tax) | K22: =SUM(K18:K20) -> 14451.31
B24: TOTAL 2 Wireless weather matic rain and freeze sensor: (This DOES NOT include sales tax)
B26: GRAND TOTAL: (This DOES NOT include sales tax) | K26: =SUM(K22:K24) -> 14451.31
B28: For further assistance you may contact:
C30: Wizard Herrera
C31: Irrigation Manager
C32: LI23286
C33: Wizard.Herrera@brightview.com
C34: Mobile: (512)769-4922
C35: Phone: (512)266-3167
C36: Fax: (512)266-7613
A38: (Please check ( √ ) all that apply)
B39: We want both CRITICAL AND NON-CRITICAL repairs to be completed by Brightview Landscapes, LLC
B40: We want ONLY CRITICAL repairs to be completed by Brightview Landscapes, LLC
B41: We want ONLY NON-CRITICAL repairs to be completed by Brightview Landscapes, LLC
B42: We want ONLY MODIFICATIONS to be completed by Brightview Landscapes, LLC
B43: We want ALL REPAIRS INCLUDING MODIFICATIONS to be completed by Brightview Landscapes, LLC
A46: Signature | I46: Date
A48: *Irrigation in Texas is regulated by the TCEQ, MC-178 * P.O. Box 13087 * Austin, Texas 78711-3087 * WWW.TCEQ.STATE.TX.US

Sheet Controller A (1)
R1: Controller Type: | BG1: 1/4
R2: Weather Matic
R3: Location: | AP3: Rain/Freeze Sensor: | AV3: Y | AY3: Rain/Freeze Sensor Type:
R4: Right back corner | AV4: N | AW4: X
AS5: Air Card: | AV5: Y | AY5: Air Card #:
C6: Job Name: | G6: Amazon | AV6: N | AW6: X
C7: Address: | G7: 2956 Main Street | R7: Water Days & Start Times: | AP7: Backflow Prevention & Meters:
C8: City & Zip: | G8: Buda, Texas | R8: A: | S8: Fri | AC8: C: | AD8: FRI | AU8: Size: | AW8: Location:
C9: Job #: | R9: A: | S9: 7PM-9PM- | AC9: C: | AD9: 7PM-9PM- | AP9: 1 | AQ9: RPZ | AU9: 2" | AW9: RIGHT SIDE ENRTY AMAZON SIGN
C10: Date: | G10: 5.6.26 | AP10: 2 | AQ10: RPZ | AU10: 2" | AW10: RIGHT SIDE ENRTY AMAZON SIGN
C11: Checked by: | G11: Julio - Henry | R11: B: | S11: M-W-THU | AC11: D: | AP11: 3
C12: Manager: | G12: Wizard Herrera/ | R12: B: | S12: 12am | AC12: D: | AP12: 4
R13: Critical Repairs | AR13: Non-Critical Repairs
A14: zones # | B14: location | C14: Rotary | D14: Spray | E14: Bubbler | F14: Drip | G14: Turf | H14: Beds | I14: Flowers | J14: Program | K14: Run Time | L14: Precipitation Rate | M14: Total # of 4"heads | N14: Total # of 6" heads | O14: Total # of 12" heads | P14: MP Rotors | Q14: GPM | R14: Nozzles (Regular) | S14: Nozzles (Toro) | T14: Nozzles (MP) | U14: 4" Heads (1804) | V14: 4" Head PRS sams (1804) | W14: 6" Heads (1806) | X14: 12" Heads (1812) | Y14: Swing | Z14: Rotors (PGP Ultra) | AA14: Drip Break | AB14: Small Line Break | AC14: Large Line Break | AD14: 2" Valve | AE14: 1 ½" Valve | AF14: 1" Valve | AG14: Decoder | AH14: Solenoid | AI14: Diaphragm | AJ14: Main Line Leak | AK14: 10" Valve Box Top | AL14: 10" Valve Box | AM14: 6" Valve Box Top | AN14: 6" Valve Box | AO14: Bubblers | AP14: Cut Wires | AQ14: Add a Zone | AR14: Nozzles (Regular) | AS14: Nozzles (Toro) | AT14: Nozzles (MP) | AU14: 4" Heads (1804) | AV14: 4" Head PRS sams (1804) | AW14: 6" Heads (1806) | AX14: 12" Heads (1812) | AY14: Aircard | AZ14: Swing | BA14: Rotors (PGP Ultra) | BB14: Raise | BC14: Lower | BD14: Move | BE14: Add Spray Heads | BF14: Add Rotory Heads | BG14: Cap Heads | BH14: Mower Damage
A15: 1 | B15: Front of controller | D15: X | G15: X | J15: A | K15: 5 | R15: 4 | U15: 1 | AE15: 1 | BB15: 3
A16: 2 | B16: Front of controller | D16: X | G16: X | J16: A | K16: 5 | R16: 1 | BB16: 3
A17: 3 | B17: Right back corner of bldg | D17: X | G17: X | J17: A | K17: 5 | AE17: 1 | AJ17: Not Activating
A18: 4 | B18: Back of bldg in river rock | E18: X | J18: B | K18: 5 | R18: 1 | U18: 1 | AC18: 1
A19: 5 | D19: X | G19: X | J19: A | K19: 5 | R19: 3 | AC19: 2
A20: 6 | B20: Front left of Building | D20: X | G20: X | J20: A | K20: 5 | R20: 1 | U20: 1
A21: 7 | B21: in front of Amazon W005 door | D21: X | G21: X | J21: A | K21: 5 | R21: 2 | U21: 2 | AC21: 1
A22: 8 | B22: Front left of Building | E22: X | J22: B | K22: 5 | Y22: No work | AE22: 1
A23: 9 | B23: Right side main entry | D23: X | G23: X | J23: A | K23: 5 | R23: 3 | AL23: 1 | BB23: 4
A24: 10 | B24: Left side main entry | D24: X | G24: X | J24: A | K24: 5 | R24: 5 | U24: 5 | AL24: 1 | BB24: 8
A25: 11 | B25: Entry along sidewalk | D25: X | G25: X | J25: A | K25: 5 | U25: 1 | AL25: 1
A26: 12 | B26: Front retention pond | C26: X | G26: X | J26: A | K26: 10 | Z26: 6
A27: 13 | B27: Second entry side walk | D27: X | G27: X | J27: A | K27: 5 | AC27: 1 | AJ27: 1
A28: 14 | B28: Second entry by pond | D28: X | G28: X | J28: A | K28: 5 | R28: 1 | V28: 1 | AA28: 1 | AC28: 1 | AL28: 1
A29: 15 | B29: Right side second entry | C29: X | G29: X | J29: A | K29: 10 | AD29: 2
A30: 16 | B30: Left side of building island | D30: X | G30: X | J30: A | K30: 5 | R30: 3 | U30: 3 | AC30: 1
A31: 17 | B31: Front right side enrty parking lot | F31: X | H31: X | J31: B | K31: 20 | AA31: 1
A32: 18 | B32: Front left enrty parking lot | F32: X | H32: X | J32: B | K32: 20 | AA32: 1
A33: 19 | J33: B | K33: 20 | X33: no work | AD33: 1
A34: 20 | J34: A | K34: 5 | X34: no work | AD34: 1
A35: 21 | J35: A | K35: 5 | X35: no work | AD35: 1
A36: 22 | B36: Front building parking lot | C36: X | G36: X | J36: A | K36: 10 | BB36: 7
A37: 23 | B37: Front building parking lot | C37: X | G37: X | J37: C | K37: 10 | BB37: 5
A38: 24 | B38: Right side second entry | D38: X | G38: X | J38: C | K38: 5 | R38: 3 | U38: 3 | AC38: 2 | BD38: 5
A39: 25 | B39: Left side island | D39: X | G39: X | J39: C | K39: 5 | R39: 5 | U39: 1
B40: Total | M40: =SUM(M15:M39) -> 0 | N40: =SUM(N15:N39) -> 0 | O40: =SUM(O15:O39) -> 0 | P40: =SUM(P15:P39) -> 0 | Q40: =SUM(Q15:Q39) -> 0 | R40: 22 | S40: =SUM(S15:S39) -> 0 | U40: =SUM(U15:U39) -> 18 | Y40: =SUM(Y15:Y39) -> 0 | AA40: =SUM(AA15:AA39) -> 3 | AC40: =SUM(AC15:AC39) -> 9 | AD40: =SUM(AD15:AD39) -> 5 | AG40: =SUM(AG15:AG39) -> 0 | AH40: =SUM(AH15:AH39) -> 0 | AK40: =SUM(AK15:AK39) -> 0 | AL40: 3 | AO40: =SUM(AO15:AO39) -> 0 | AP40: =SUM(AP15:AP39) -> 0
...

Sheet Controller A(2)
R1: Controller Type: | BG1: 1/4
R2: Weather Matic
R3: Location: | AP3: Rain/Freeze Sensor: | AV3: Y | AY3: Rain/Freeze Sensor Type:
R4: Left front side of building Amazon door | AV4: N | AW4: X
AS5: Air Card: | AV5: Y | AY5: Air Card #:
C6: Job Name: | G6: Amazon | AV6: N | AW6: X
C7: Address: | G7: 2956 Main Street | R7: Water Days & Start Times: | AP7: Backflow Prevention & Meters:
C8: City & Zip: | G8: Buda, Texas | R8: A: | AC8: C: | AU8: Size: | AW8: Location:
C9: Job #: | R9: A: | AC9: C: | AP9: 1 | AQ9: RPZ | AU9: 2" | AW9: RIGHT SIDE ENRTY AMAZON SIGN
C10: Date: | G10: 9.25.2024 | AP10: 2 | AQ10: RPZ | AU10: 2" | AW10: RIGHT SIDE ENRTY AMAZON SIGN
C11: Checked by: | G11: Rene | R11: B: | AC11: D: | AP11: 3
C12: Manager: | G12: Wizard Herrera/ | R12: B: | AC12: D: | AP12: 4
R13: Critical Repairs | AR13: Non-Critical Repairs
A14: zones # | B14: location | C14: Rotary | D14: Spray | E14: Bubbler | F14: Drip | G14: Turf | H14: Beds | I14: Flowers | J14: Program | K14: Run Time | L14: Precipitation Rate | M14: Total # of 4"heads | N14: Total # of 6" heads | O14: Total # of 12" heads | P14: MP Rotors | Q14: GPM | R14: Nozzles (Regular) | S14: Nozzles (Toro) | T14: Nozzles (MP) | U14: 4" Heads (1804) | V14: 4" Head PRS sams (1804) | W14: 6" Heads (1806) | X14: 12" Heads (1812) | Y14: Swing | Z14: Rotors (PGP Ultra) | AA14: Drip Break | AB14: Small Line Break | AC14: Large Line Break | AD14: 2" Valve | AE14: 1 ½" Valve | AF14: 1" Valve | AG14: Decoder | AH14: Solenoid | AI14: Diaphragm | AJ14: Main Line Leak | AK14: 10" Valve Box Top | AL14: 10" Valve Box | AM14: 6" Valve Box Top | AN14: 6" Valve Box | AO14: Bubblers | AP14: Cut Wires | AQ14: Add a Zone | AR14: Nozzles (Regular) | AS14: Nozzles (Toro) | AT14: Nozzles (MP) | AU14: 4" Heads (1804) | AV14: 4" Head PRS sams (1804) | AW14: 6" Heads (1806) | AX14: 12" Heads (1812) | AY14: Aircard | AZ14: Swing | BA14: Rotors (PGP Ultra) | BB14: Raise | BC14: Lower | BD14: Move | BE14: Add Spray Heads | BF14: Add Rotory Heads | BG14: Cap Heads | BH14: Mower Damage
A15: 26 | B15: Left side of building island | E15: X | J15: B | K15: 5 | AO15: 2
A16: 27 | B16: Along second retention pond | F16: X | H16: X | J16: B | K16: 20
A17: 28 | B17: Front second retention pond | C17: X | G17: X | J17: C | K17: 10 | Z17: 2 | AL17: 1
A18: 29 | B18: Left side island | D18: X | G18: X | J18: C | K18: 5
A19: 30 | B19: Alond side walk second entry | C19: X | G19: X | J19: C | K19: 10 | Z19: 2
A20: 31 | B20: Left side of building island | D20: X | G20: X | J20: C | K20: 5 | R20: 1 | BB20: 4
A21: 32 | B21: Left side along exit | D21: X | G21: X | J21: C | K21: 5 | R21: 2 | AK21: 1 | BB21: 6
A22: 33 | B22: Along left side building | D22: X | G22: X | J22: C | K22: 5 | R22: 2 | U22: 2 | AC22: 1 | BB22: 8
A23: 34 | B23: Left island | D23: X | G23: X | J23: C | K23: 5 | R23: 2 | Y23: 1 | AC23: 1 | AO23: 1 | BB23: 5
A24: 35 | B24: Left of building parking lot | E24: X | J24: B | K24: 5 | Y24: 1 | AO24: 3
A25: 36 | B25: Back left parking lot | D25: X | G25: X | J25: C | K25: 5 | R25: 2 | U25: 1 | BD25: 9
A26: 37 | B26: Back island parking lot | D26: X | G26: X | J26: C | K26: 5 | R26: 1 | U26: 1 | BD26: 11
A27: 38 | B27: Back left parking lot | D27: X | G27: X | J27: C | K27: 5 | AB27: 1
A28: 39 | B28: Back left side parking lot | D28: X | G28: X | J28: C | K28: 5 | AC28: 1
A29: 40 | B29: Back of Building | C29: X | G29: X | J29: C | K29: 10
A30: 41 | B30: South side parking lot | C30: X | G30: X | J30: C | K30: 10
A31: 42 | B31: South side parking lot | E31: X | J31: B | K31: 5 | AC31: 1
A32: 43 | AE32: 1 | AP32: 1
A33: 44 | B33: South side island | D33: X | G33: X | J33: A | K33: 5 | AC33: 1
A34: 45 | B34: South side parking lot | C34: X | G34: X | J34: A | K34: 10 | AK34: 1
A35: 46 | B35: Along back exit | D35: X | G35: X | J35: A | K35: 5 | R35: 1 | U35: 1
A36: 47 | B36: South side parking lot | D36: X | G36: X | J36: A | K36: 5 | R36: 2 | AC36: 1
A37: 48 | B37: Along south exit | D37: X | G37: X | J37: A | K37: 5 | AJ37: 1
A38: 49
A39: 50
B40: Total | M40: =SUM(M15:M39) -> 0 | N40: =SUM(N15:N39) -> 0 | O40: =SUM(O15:O39) -> 0 | P40: =SUM(P15:P39) -> 0 | Q40: =SUM(Q15:Q39) -> 0 | R40: 7 | S40: =SUM(S15:S39) -> 0 | U40: =SUM(U15:U39) -> 5 | Y40: =SUM(Y15:Y39) -> 2 | Z40: 9 | AA40: =SUM(AA15:AA39) -> 0 | AB40: =SUM(AB15:AB39) -> 1 | AC40: =SUM(AC15:AC39) -> 6 | AD40: =SUM(AD15:AD39) -> 0 | AE40: 1 | AO40: =SUM(AO15:AO39) -> 6 | AP40: =SUM(AP15:AP39) -> 1
...

Sheet 7(1)-Comp
C9: 1814 W. Howard Ln. | K9: Phone: (512)266-3167
C10: Austin, TX 78728 | K10: Fax (512)266-7613
D13: Job Name: | F13: ='Controller A(2)'!G6 -> Amazon
D14: Job #: | F14: ='Controller A(2)'!G9 -> 0
D15: Inspection Date: | F15: ='Controller A(2)'!G10 -> 9.25.2024
C18: Critical Repairs Needed
C20: QTY: | D20: Items: | E20: Cost Ea. | G20: Cost for Labor & Parts
C21: ='Controller A(2)'!R40 -> 7 | D21: Nozzles - Reg | E21: 2 | F21: =C21*E21 -> 14 | G21: + | H21: =SUM(80/I21)*C21 -> 18.666667 | I21: 30 | J21: = | K21: =F21+H21 -> 32.666667
C22: 19 | D22: Nozzles - Toro | E22: 4.25 | F22: =C22*E22 -> 80.75 | G22: + | H22: =SUM(80/I22)*C22 -> 50.666667 | I22: 30 | K22: =F22+H22 -> 131.41667
C23: ='Controller A(2)'!T40 -> 0 | D23: MP Nozzles | E23: 10 | F23: =C23*E23 -> 0 | G23: + | H23: =SUM(80/I23)*C23 -> 0 | I23: 12 | J23: = | K23: =F23+H23 -> 0
C24: 19 | D24: 4" Heads | E24: 4 | F24: =C24*E24 -> 76 | G24: + | H24: =SUM(80/I24)*C24 -> 217.14286 | I24: 7 | J24: = | K24: =F24+H24 -> 293.14286
C25: ='Controller A(2)'!V40 -> 0 | D25: 4" Head PRS Sams | E25: 8 | F25: =C25*E25 -> 0 | G25: + | H25: =SUM(80/I24)*C25 -> 0 | I25: 7 | J25: = | K25: =F25+H25 -> 0
C26: ='Controller A(2)'!W40 -> 0 | D26: 6" Heads | E26: 7 | F26: =C26*E26 -> 0 | G26: + | H26: =SUM(80/I26)*C26 -> 0 | I26: 6 | J26: = | K26: =F26+H26 -> 0
C27: ='Controller A(2)'!X40 -> 0 | D27: 12" Heads | E27: 15 | F27: =C27*E27 -> 0 | G27: + | H27: =SUM(80/I27)*C27 -> 0 | I27: 3 | J27: = | K27: =F27+H27 -> 0
C28: 143 | D28: Swing | E28: 3.5 | F28: =C28*E28 -> 500.5 | G28: + | H28: =SUM(80/I28)*C28 -> 1634.2857 | I28: 7 | J28: = | K28: =F28+H28 -> 2134.7857
C29: ='Controller A(2)'!Z40 -> 9 | D29: Rotors | E29: 20 | F29: =C29*E29 -> 180 | G29: + | H29: =SUM(80/I29)*C29 -> 180 | I29: 4 | J29: = | K29: =F29+H29 -> 360
C30: 14 | D30: Drip Break | E30: 5.25 | F30: =C30*E30 -> 73.5 | G30: + | H30: =SUM(15*I30)*C30 -> 69.3 | I30: 0.33 | J30: = | K30: =F30+H30 -> 142.8
C31: 4 | D31: Line Break - Sm | E31: 34.5 | F31: =C31*E31 -> 138 | G31: + | H31: =SUM(80/I31)*C31 -> 160 | I31: 2 | J31: = | K31: =F31+H31 -> 298
C32: 19 | D32: Line Break - Lg | E32: 50 | F32: =C32*E32 -> 950 | G32: + | H32: =SUM(80/I32)*C32 -> 1520 | I32: 1 | K32: =F32+H32 -> 2470
C33: 11 | D33: 2" Valve | E33: 135 | F33: =C33*E33 -> 1485 | G33: + | H33: =SUM(80/I33)*C33 -> 1760 | I33: 0.5 | J33: = | K33: =F33+H33 -> 3245
C34: ='Controller A(2)'!AE40 -> 1 | D34: 1 ½" Valve | E34: 115 | F34: =C34*E34 -> 115 | G34: + | H34: =SUM(80/I34)*C34 -> 80 | I34: 1 | J34: = | K34: =F34+H34 -> 195
C35: ='Controller A(2)'!AF40 -> 0 | D35: 1" Valve | E35: 75 | F35: =C35*E35 -> 0 | G35: + | H35: =SUM(80/I35)*C35 -> 0 | I35: 2 | J35: = | K35: =F35+H35 -> 0
C36: 8 | D36: Decoder | E36: 138 | F36: =C36*E36 -> 1104 | G36: + | H36: =SUM(80/I36)*C36 -> 640 | I36: 1 | J36: = | K36: =F36+H36 -> 1744
C37: ='Controller A(2)'!AH40 -> 0 | D37: Solenoid | E37: 30 | F37: =C37*E37 -> 0 | G37: + | H37: =SUM(80/I37)*C37 -> 0 | I37: 2 | J37: = | K37: =F37+H37 -> 0
C38: ='Controller A(2)'!AI40 -> 0 | D38: Diaphragm | E38: 30 | F38: =C38*E38 -> 0 | G38: + | H38: =SUM(80/I38)*C38 -> 0 | I38: 2 | J38: = | K38: =F38+H38 -> 0
C39: ='Controller A(2)'!AJ40 -> 0 | D39: Main Line Leak | E39: 246 | F39: =C39*E39 -> 0 | G39: + | H39: =SUM(80/I39)*C39 -> 0 | I39: 0.5 | J39: = | K39: =F39+H39 -> 0
C40: ='Controller A(2)'!AK40 -> 0 | D40: 10" Valve Box Top | E40: 11.5 | F40: =C40*E40 -> 0 | G40: + | H40: =SUM(80/I40)*C40 -> 0 | I40: 30 | J40: = | K40: =F40+H40 -> 0
C41: ='Controller A(2)'!AL40 -> 0 | D41: 10" Valve Box | E41: 20 | F41: =C41*E41 -> 0 | G41: + | H41: =SUM(80/I41)*C41 -> 0 | I41: 30 | J41: = | K41: =F41+H41 -> 0
C42: ='Controller A(2)'!AM40 -> 0 | D42: 6" Valve Box Top | E42: 7.5 | F42: =C42*E42 -> 0 | G42: + | H42: =SUM(80/I42)*C42 -> 0 | I42: 30 | J42: = | K42: =F42+H42 -> 0
C43: ='Controller A(2)'!AN40 -> 0 | D43: 6" Valve Box | E43: 10 | F43: =C43*E43 -> 0 | G43: + | H43: =SUM(80/I43)*C43 -> 0 | I43: 30 | J43: = | K43: =F43+H43 -> 0
C44: ='Controller A(2)'!AO40 -> 6 | D44: Bubblers | E44: 5.75 | F44: =C44*E44 -> 34.5 | G44: + | H44: =SUM(80/I44)*C44 -> 80 | I44: 6 | J44: = | K44: =F44+H44 -> 114.5
C45: 19 | D45: Cut wires | E45: 115 | F45: =C45*E45 -> 2185 | G45: + | H45: =SUM(80*I45)*C45 -> 760 | I45: 0.5 | J45: = | K45: =F45+H45 -> 2945
C46: ='Controller A(2)'!AQ40 -> 0 | D46: Add A Zone | E46: 125 | F46: =C46*E46 -> 0 | G46: + | H46: =SUM(80/I46)*C46 -> 0 | I46: 1 | J46: = | K46: =F46+H46 -> 0
J47: TOTAL | K47: =SUM(K21:K46) -> 14106.312
C49: Non-Critical Repairs Needed
C51: QTY: | D51: Items: | G51: Cost for Labor & Parts
C52: ='Controller A(2)'!AR40 -> 0 | D52: Nozzles - Reg | E52: 2 | F52: =C52*E52 -> 0 | G52: + | H52: =SUM(80/I52)*C52 -> 0 | I52: 30 | J52: = | K52: =F52+H52 -> 0
C53: ='Controller A(2)'!AS40 -> 0 | D53: Nozzles - Toro | E53: 4.25 | F53: =C53*E53 -> 0 | G53: + | H53: =SUM(80/I53)*C53 -> 0 | I53: 30 | K53: =F53+H53 -> 0
C54: ='Controller A(2)'!AT40 -> 0 | D54: MP Nozzles | E54: 10 | F54: =C54*E54 -> 0 | G54: + | H54: =SUM(80/I54)*C54 -> 0 | I54: 12 | J54: = | K54: =F54+H54 -> 0
C55: ='Controller A(2)'!AU40 -> 0 | D55: 4" Heads | E55: 4 | F55: =C55*E55 -> 0 | G55: + | H55: =SUM(80/I55)*C55 -> 0 | I55: 7 | J55: = | K55: =F55+H55 -> 0
...

Sheet 7(2)-Comp
C9: 1814 W. Howard Ln. | K9: Phone: (512)266-3167
C10: Austin, TX 78728 | K10: Fax (512)266-7613
D13: Job Name: | F13: =#REF! -> #REF!
D14: Job #: | F14: =#REF! -> #REF!
D15: Inspection Date: | F15: =#REF! -> #REF!
C18: Critical Repairs Needed
C20: QTY: | D20: Items: | E20: Cost Ea. | G20: Cost for Labor & Parts
C21: =#REF! -> #REF! | D21: Nozzles - Reg | E21: 2 | F21: =C21*E21 -> #REF! | G21: + | H21: =SUM(80/I21)*C21 -> #REF! | I21: 30 | J21: = | K21: =F21+H21 -> #REF!
C22: =#REF! -> #REF! | D22: Nozzles - Toro | E22: 4.25 | F22: =C22*E22 -> #REF! | G22: + | H22: =SUM(80/I22)*C22 -> #REF! | I22: 30 | K22: =F22+H22 -> #REF!
C23: =#REF! -> #REF! | D23: MP Nozzles | E23: 10 | F23: =C23*E23 -> #REF! | G23: + | H23: =SUM(80/I23)*C23 -> #REF! | I23: 12 | J23: = | K23: =F23+H23 -> #REF!
C24: =#REF! -> #REF! | D24: 4" Heads | E24: 4 | F24: =C24*E24 -> #REF! | G24: + | H24: =SUM(80/I24)*C24 -> #REF! | I24: 7 | J24: = | K24: =F24+H24 -> #REF!
C25: =#REF! -> #REF! | D25: 4" Head PRS Sams | E25: 8 | F25: =C25*E25 -> #REF! | G25: + | H25: =SUM(80/I24)*C25 -> #REF! | I25: 7 | J25: = | K25: =F25+H25 -> #REF!
C26: =#REF! -> #REF! | D26: 6" Heads | E26: 7 | F26: =C26*E26 -> #REF! | G26: + | H26: =SUM(80/I26)*C26 -> #REF! | I26: 6 | J26: = | K26: =F26+H26 -> #REF!
C27: =#REF! -> #REF! | D27: 12" Heads | E27: 15 | F27: =C27*E27 -> #REF! | G27: + | H27: =SUM(80/I27)*C27 -> #REF! | I27: 3 | J27: = | K27: =F27+H27 -> #REF!
C28: =#REF! -> #REF! | D28: Swing | E28: 3.5 | F28: =C28*E28 -> #REF! | G28: + | H28: =SUM(80/I28)*C28 -> #REF! | I28: 7 | J28: = | K28: =F28+H28 -> #REF!
C29: =#REF! -> #REF! | D29: Rotors | E29: 20 | F29: =C29*E29 -> #REF! | G29: + | H29: =SUM(80/I29)*C29 -> #REF! | I29: 4 | J29: = | K29: =F29+H29 -> #REF!
C30: =#REF! -> #REF! | D30: Drip Break | E30: 5.25 | F30: =C30*E30 -> #REF! | G30: + | H30: =SUM(15*I30)*C30 -> #REF! | I30: 0.33 | J30: = | K30: =F30+H30 -> #REF!
C31: =#REF! -> #REF! | D31: Line Break - Sm | E31: 34.5 | F31: =C31*E31 -> #REF! | G31: + | H31: =SUM(80/I31)*C31 -> #REF! | I31: 2 | J31: = | K31: =F31+H31 -> #REF!
C32: =#REF! -> #REF! | D32: Line Break - Lg | E32: 50 | F32: =C32*E32 -> #REF! | G32: + | H32: =SUM(80/I32)*C32 -> #REF! | I32: 1 | K32: =F32+H32 -> #REF!
C33: =#REF! -> #REF! | D33: 2" Valve | E33: 135 | F33: =C33*E33 -> #REF! | G33: + | H33: =SUM(80/I33)*C33 -> #REF! | I33: 0.5 | J33: = | K33: =F33+H33 -> #REF!
C34: =#REF! -> #REF! | D34: 1 ½" Valve | E34: 115 | F34: =C34*E34 -> #REF! | G34: + | H34: =SUM(80/I34)*C34 -> #REF! | I34: 1 | J34: = | K34: =F34+H34 -> #REF!
C35: =#REF! -> #REF! | D35: 1" Valve | E35: 75 | F35: =C35*E35 -> #REF! | G35: + | H35: =SUM(80/I35)*C35 -> #REF! | I35: 2 | J35: = | K35: =F35+H35 -> #REF!
C36: =#REF! -> #REF! | D36: Decoder | E36: 138 | F36: =C36*E36 -> #REF! | G36: + | H36: =SUM(80/I36)*C36 -> #REF! | I36: 1 | J36: = | K36: =F36+H36 -> #REF!
C37: =#REF! -> #REF! | D37: Solenoid | E37: 30 | F37: =C37*E37 -> #REF! | G37: + | H37: =SUM(80/I37)*C37 -> #REF! | I37: 2 | J37: = | K37: =F37+H37 -> #REF!
C38: =#REF! -> #REF! | D38: Diaphragm | E38: 30 | F38: =C38*E38 -> #REF! | G38: + | H38: =SUM(80/I38)*C38 -> #REF! | I38: 2 | J38: = | K38: =F38+H38 -> #REF!
C39: =#REF! -> #REF! | D39: Main Line Leak | E39: 246 | F39: =C39*E39 -> #REF! | G39: + | H39: =SUM(80/I39)*C39 -> #REF! | I39: 0.5 | J39: = | K39: =F39+H39 -> #REF!
C40: =#REF! -> #REF! | D40: 10" Valve Box Top | E40: 11.5 | F40: =C40*E40 -> #REF! | G40: + | H40: =SUM(80/I40)*C40 -> #REF! | I40: 30 | J40: = | K40: =F40+H40 -> #REF!
C41: =#REF! -> #REF! | D41: 10" Valve Box | E41: 20 | F41: =C41*E41 -> #REF! | G41: + | H41: =SUM(80/I41)*C41 -> #REF! | I41: 30 | J41: = | K41: =F41+H41 -> #REF!
C42: =#REF! -> #REF! | D42: 6" Valve Box Top | E42: 7.5 | F42: =C42*E42 -> #REF! | G42: + | H42: =SUM(80/I42)*C42 -> #REF! | I42: 30 | J42: = | K42: =F42+H42 -> #REF!
C43: =#REF! -> #REF! | D43: 6" Valve Box | E43: 10 | F43: =C43*E43 -> #REF! | G43: + | H43: =SUM(80/I43)*C43 -> #REF! | I43: 30 | J43: = | K43: =F43+H43 -> #REF!
C44: =#REF! -> #REF! | D44: Bubblers | E44: 5.75 | F44: =C44*E44 -> #REF! | G44: + | H44: =SUM(80/I44)*C44 -> #REF! | I44: 6 | J44: = | K44: =F44+H44 -> #REF!
C45: =#REF! -> #REF! | D45: Cut wires | E45: 115 | F45: =C45*E45 -> #REF! | G45: + | H45: =SUM(80*I45)*C45 -> #REF! | I45: 0.5 | J45: = | K45: =F45+H45 -> #REF!
C46: =#REF! -> #REF! | D46: Add A Zone | E46: 125 | F46: =C46*E46 -> #REF! | G46: + | H46: =SUM(80/I46)*C46 -> #REF! | I46: 1 | J46: = | K46: =F46+H46 -> #REF!
J47: TOTAL | K47: =SUM(K21:K46) -> #REF!
C49: Non-Critical Repairs Needed
C51: QTY: | D51: Items: | G51: Cost for Labor & Parts
C52: =#REF! -> #REF! | D52: Nozzles - Reg | E52: 2 | F52: =C52*E52 -> #REF! | G52: + | H52: =SUM(80/I52)*C52 -> #REF! | I52: 30 | J52: = | K52: =F52+H52 -> #REF!
C53: =#REF! -> #REF! | D53: Nozzles - Toro | E53: 4.25 | F53: =C53*E53 -> #REF! | G53: + | H53: =SUM(80/I53)*C53 -> #REF! | I53: 30 | K53: =F53+H53 -> #REF!
C54: =#REF! -> #REF! | D54: MP Nozzles | E54: 10 | F54: =C54*E54 -> #REF! | G54: + | H54: =SUM(80/I54)*C54 -> #REF! | I54: 12 | J54: = | K54: =F54+H54 -> #REF!
C55: =#REF! -> #REF! | D55: 4" Heads | E55: 4 | F55: =C55*E55 -> #REF! | G55: + | H55: =SUM(80/I55)*C55 -> #REF! | I55: 7 | J55: = | K55: =F55+H55 -> #REF!
...

Sheet Controller A (3)
R1: Controller Type: | BG1: 4/4
R3: Location: | AP3: Rain/Freeze Sensor: | AV3: Y | AW3: X | AY3: Rain/Freeze Sensor Type:
AV4: N
AS5: Air Card: | AV5: Y | AY5: Air Card #:
C6: Job Name: | G6: ='Controller A(2)'!G6 -> Amazon | AV6: N
C7: Address: | G7: ='Controller A(2)'!G7 -> 2956 Main Street | R7: Water Days & Start Times: | AP7: Backflow Prevention & Meters:
C8: City & Zip: | G8: ='Controller A(2)'!G8 -> Buda, Texas | R8: A: | AC8: C: | AU8: Size: | AW8: Location:
C9: Job #: | R9: A: | AC9: C: | AP9: 1 | AQ9: RPZ | AU9: 2" | AW9: RIGHT SIDE ENTRY TO AMAZON SIGN
C10: Date: | G10: 9.25.2024 | AP10: 2 | AQ10: RPZ | AU10: 2" | AW10: RIGHT SIDE ENTRY TO AMAZON SIGN
C11: Checked by: | R11: B: | AC11: D: | AP11: 3
C12: Manager: | G12: ='Controller A(2)'!G12 -> Wizard Herrera/ | R12: B: | AC12: D: | AP12: 4
R13: Critical Repairs | AR13: Non-Critical Repairs
A14: zones # | B14: location | C14: Rotary | D14: Spray | E14: Bubbler | F14: Drip | G14: Turf | H14: Beds | I14: Flowers | J14: Program | K14: Run Time | L14: Precipitation Rate | M14: Total # of 4"heads | N14: Total # of 6" heads | O14: Total # of 12" heads | P14: MP Rotors | Q14: GPM | R14: Nozzles (Regular) | S14: Nozzles (Toro) | T14: Nozzles (MP) | U14: 4" Heads (1804) | V14: 4" Head PRS sams (1804) | W14: 6" Heads (1806) | X14: 12" Heads (1812) | Y14: Swing | Z14: Rotors (PGP Ultra) | AA14: Drip Break | AB14: Small Line Break | AC14: Large Line Break | AD14: 2" Valve | AE14: 1 ½" Valve | AF14: 1" Valve | AG14: Decoder | AH14: Solenoid | AI14: Diaphragm | AJ14: Main Line Leak | AK14: 10" Valve Box Top | AL14: 10" Valve Box | AM14: 6" Valve Box Top | AN14: 6" Valve Box | AO14: Bubblers | AP14: Cut Wires | AQ14: SVC | AR14: Nozzles (Regular) | AS14: Nozzles (Toro) | AT14: Nozzles (MP) | AU14: 4" Heads (1804) | AV14: 4" Head PRS sams (1804) | AW14: 6" Heads (1806) | AX14: 12" Heads (1812) | AY14: Aircard | AZ14: Swing | BA14: Rotors (PGP Ultra) | BB14: Raise | BC14: Lower | BD14: Move | BE14: Add Spray Heads | BF14: Add Rotory Heads | BG14: Cap Heads | BH14: Mower Damage
A15: 51 | B15: Back along buikding SVC | E15: X | J15: E | K15: 5 | V15: NEED NEW SVC | AB15: 1 | AO15: 1 | AQ15: 1
A16: 52 | B16: Back north parking lot SVC | D16: X | G16: X | J16: D | K16: 5 | V16: Need replace svc | AC16: 1
A17: 53 | B17: Norht back parking lot SVC | D17: X | G17: X | J17: D | K17: 5 | R17: 1 | U17: 1 | V17: Need replace svc
A18: 54 | B18: Back of Building SVC | C18: X | G18: X | J18: D | K18: 10 | AC18: 1 | AJ18: 1
A19: 55 | B19: Back 301 island SVC | D19: X | G19: X | J19: D | K19: 5 | S19: NEED BATTERIES
A20: 56 | B20: CVC north island SVC | D20: X | G20: X | J20: D | K20: 5 | R20: 6 | U20: 4 | AC20: 1 | AQ20: 1
A21: 57 | B21: CVC north island SVC | D21: X | G21: X | J21: D | K21: 5 | AQ21: 1
A22: 58 | B22: Nort island SVC | D22: X | G22: X | J22: D | K22: 5 | S22: NEED BATTERIES | W22: IES
A23: 59 | B23: CVC around pond 3 SVC | C23: X | G23: X | J23: D | K23: 10 | Z23: 5 | AJ23: 1
A24: 60 | B24: CVC around pond 3 SVC | E24: X | J24: E | K24: 5 | AO24: 1
A25: 36
A26: 37
A27: 38
A28: 39
A29: 40
A30: 41
A31: 42
A32: 43
A33: 44
A34: 45
A35: 46
A36: 47
... A39: 50
B40: Total | M40: =SUM(M15:M39) -> 0 | N40: =SUM(N15:N39) -> 0 | O40: =SUM(O15:O39) -> 0 | P40: =SUM(P15:P39) -> 0 | Q40: =SUM(Q15:Q39) -> 0 | R40: =SUM(R15:R39) -> 7 | S40: =SUM(S15:S39) -> 0 | T40: =SUM(T15:T39) -> 0 | ... BH40: =SUM(BH15:BH39) -> 0
B41: Notes:

Sheet Controller B(1)
F1: X | R1: Controller Type: | BG1: 3/4
R2: Weather Matic
R3: Location: | AP3: Rain/Freeze Sensor: | AV3: Y | AY3: Rain/Freeze Sensor Type:
R4: FACP ROOM WO47 | AV4: N | AW4: X
AS5: Air Card: | AV5: Y | AY5: Air Card #:
C6: Job Name: | G6: ='Controller A(2)'!G6 -> Amazon | AV6: N | AW6: X
C7: Address: | G7: ='Controller A(2)'!G7 -> 2956 Main Street | R7: Water Days & Start Times: | AP7: Backflow Prevention & Meters:
C8: City & Zip: | G8: ='Controller A(2)'!G8 -> Buda, Texas | R8: A: | S8: TUE-THUR | AC8: C: | AU8: Size: | AW8: Location:
C9: Job #: | R9: A: | S9: 8PM-10PM- | AC9: C: | AP9: 1 | AQ9: RPZ | AU9: 2" | AW9: RIGHT SIDE ENTRY AMAZON SIGN
C10: Date: | AP10: 2
C11: Checked by: | R11: B: | S11: M-W-SAT-SUN | AC11: D: | AP11: 3
C12: Manager: | G12: ='Controller A(2)'!G12 -> Wizard Herrera/ | R12: B: | S12: 10PM- | AC12: D: | AP12: 4
R13: Critical Repairs | AR13: Non-Critical Repairs
A14: zones # | B14: location | C14: Rotary | D14: Spray | E14: Bubbler | F14: Drip | G14: Turf | H14: Beds | I14: Flowers | J14: Program | K14: Run Time | L14: Precipitation Rate | M14: Total # of 4"heads | N14: Total # of 6" heads | O14: Total # of 12" heads | P14: MP Rotors | Q14: GPM | R14: Nozzles (Regular) | S14: Nozzles (Toro) | T14: Nozzles (MP) | U14: 4" Heads (1804) | V14: 4" Head PRS sams (1804) | W14: 6" Heads (1806) | X14: 12" Heads (1812) | Y14: Swing | Z14: Rotors (PGP Ultra) | AA14: Drip Break | AB14: Small Line Break | AC14: Large Line Break | AD14: 2" Valve | AE14: 1 ½" Valve | AF14: 1" Valve | AG14: Decoder | AH14: Solenoid | AI14: Diaphragm | AJ14: Main Line Leak | AK14: 10" Valve Box Top | AL14: 10" Valve Box | AM14: 6" Valve Box Top | AN14: 6" Valve Box | AO14: Bubblers | AP14: Cut Wires | AQ14: Add a Zone | AR14: Nozzles (Regular) | AS14: Nozzles (Toro) | AT14: Nozzles (MP) | AU14: 4" Heads (1804) | AV14: 4" Head PRS sams (1804) | AW14: 6" Heads (1806) | AX14: 12" Heads (1812) | AY14: Aircard | AZ14: Swing | BA14: Rotors (PGP Ultra) | BB14: Raise | BC14: Lower | BD14: Move | BE14: Add Spray Heads | BF14: Add Rotory Heads | BG14: Cap Heads | BH14: Mower Damage
A15: 1 | B15: Front of controller | D15: X | G15: X | J15: A | K15: 5 | S15: 2 | U15: 1
A16: 2 | B16: Front of controller | D16: X | G16: X | J16: A | K16: 5 | U16: 1
A17: 3 | B17: Front of EO-19 | D17: X | G17: X | J17: A | K17: 5 | R17: 2 | U17: 1 | Y17: 1
A18: 4 | B18: Front of EO-18 | D18: X | G18: X | J18: A | K18: 5 | R18: 4 | U18: 2 | Y18: 2 | AD18: 1
A19: 5 | B19: Front of EO-12 | D19: X | G19: X | J19: A | K19: 5 | R19: 2 | U19: 2 | Y19: 2 | AD19: 1
A20: 6 | B20: Front of EO-16 NA | D20: X | G20: X | J20: A | K20: 5 | R20: 3 | U20: 2 | Y20: 2 | AD20: 1
A21: 7 | B21: Front of EO-15-EO19 | E21: X | G21: X | J21: B | K21: 10
A22: 8 | B22: Front of 301 dock | D22: X | G22: X | J22: B | K22: 10 | AC22: 1
A23: 9 | B23: Front of bldg | E23: X | J23: B | K23: 10 | AE23: 1
A24: 10 | B24: Along retention p-lot | C24: X | G24: X | J24: A | K24: 5 | R24: 1
A25: 11 | B25: Along retention p-lot | F25: X | H25: X | J25: A | K25: 5 | AA25: 2 | AC25: 1 | AO25: 2
A26: 12 | B26: Along retention p-lot | C26: X | G26: X | J26: A | K26: 10 | Z26: 5
A27: 13 | B27: Right of 1st entrance | D27: X | G27: X | J27: A | K27: 5 | R27: 3
A28: 14 | B28: Right of 1st entrance | D28: X | G28: X | J28: A | K28: 5 | R28: 5 | U28: 4 | AD28: 1
A29: 15 | B29: Left of entry & along sidewalk | E29: X | J29: A | K29: 5 | R29: 1 | AC29: 1 | AE29: 1
A30: 16 | B30: Along Main Street curbside | F30: X | G30: X | J30: A | K30: 5 | R30: 1 | AC30: 1 | AE30: 1
A31: 17 | B31: Left of 1st entrance | D31: X | G31: X | J31: A | K31: 5 | AC31: 1 | AL31: 1
A32: 18 | B32: Left of 1st entrance along SW | D32: X | G32: X | J32: A | K32: 5
A33: 19 | B33: Along retention by side walk | C33: X | G33: X | J33: C | K33: 10 | AE33: 1
A34: 20 | B34: Along Main Street side walk | D34: X | G34: X | J34: B | K34: 5 | AB34: 1
A35: 21 | B35: Along retention by side walk | C35: X | G35: X | J35: C | K35: 10
A36: 22 | B36: Along Main Street side walk | D36: X | G36: X | J36: C | K36: 10 | Z36: 1
A37: 23 | B37: Right of 2nd entrance by rpz | D37: X | G37: X | J37: C | K37: 10 | Z37: 1
A38: 24 | B38: NA | E38: X | J38: B | K38: 5 | AD38: 1
A39: 25 | B39: NA | D39: X | G39: X | J39: C | K39: 5 | AD39: 1
B40: Total | M40: =SUM(M15:M39) -> 0 | N40: =SUM(N15:N39) -> 0 | O40: =SUM(O15:O39) -> 0 | P40: =SUM(P15:P39) -> 0 | Q40: =SUM(Q15:Q39) -> 0 | R40: =SUM(R16:R39) -> 22 | S40: =SUM(S16:S39) -> 0 | U40: =SUM(U16:U39) -> 12 | Y40: =SUM(Y16:Y39) -> 7 | Z40: 7 | AB40: =SUM(AB16:AB39) -> 1 | AC40: =SUM(AC16:AC39) -> 5 | AD40: =SUM(AD16:AD39) -> 6 | AG40: =SUM(AG16:AG39) -> 0 | AO40: =SUM(AO16:AO39) -> 2 | AP40: =SUM(AP16:AP39) -> 0 | AQ40: 1 | BH40: =SUM(BH15:BH39) -> 0
...

Sheet Controller B(2)
R1: Controller Type: | BG1: 3/4
R2: Weather Matic
R3: Location: | AP3: Rain/Freeze Sensor: | AV3: Y | AY3: Rain/Freeze Sensor Type:
R4: right back side of building E019-DOCK137 | AV4: N | AW4: X
AS5: Air Card: | AV5: Y | AY5: Air Card #:
C6: Job Name: | G6: ='Controller A(2)'!G6 -> Amazon | AV6: N | AW6: X
C7: Address: | G7: ='Controller A(2)'!G7 -> 2956 Main Street | R7: Water Days & Start Times: | AP7: Backflow Prevention & Meters:
C8: City & Zip: | G8: ='Controller A(2)'!G8 -> Buda, Texas | R8: A: | AC8: C: | AU8: Size: | AW8: Location:
C9: Job #: | R9: A: | AC9: C: | AP9: 1 | AQ9: RPZ | AU9: 2" | AW9: RIGHT SIDE ENTRY AMAZON SIGN
C10: Date: | AP10: 2
C11: Checked by: | R11: B: | AC11: D: | AP11: 3
C12: Manager: | G12: ='Controller A(2)'!G12 -> Wizard Herrera/ | R12: B: | AC12: D: | AP12: 4
R13: Critical Repairs | AR13: Non-Critical Repairs
A14: zones # | B14: location | C14: Rotary | D14: Spray | E14: Bubbler | F14: Drip | G14: Turf | H14: Beds | I14: Flowers | J14: Program | K14: Run Time | L14: Precipitation Rate | M14: Total # of 4"heads | N14: Total # of 6" heads | O14: Total # of 12" heads | P14: MP Rotors | Q14: GPM | R14: Nozzles (Regular) | S14: Nozzles (Toro) | T14: Nozzles (MP) | U14: 4" Heads (1804) | V14: 4" Head PRS sams (1804) | W14: 6" Heads (1806) | X14: 12" Heads (1812) | Y14: Swing | Z14: Rotors (PGP Ultra) | AA14: Drip Break | AB14: Small Line Break | AC14: Large Line Break | AD14: 2" Valve | AE14: 1 ½" Valve | AF14: 1" Valve | AG14: Decoder | AH14: Solenoid | AI14: Diaphragm | AJ14: Main Line Leak | AK14: 10" Valve Box Top | AL14: 10" Valve Box | AM14: 6" Valve Box Top | AN14: 6" Valve Box | AO14: Bubblers | AP14: Cut Wires | AQ14: Add a Zone | AR14: Nozzles (Regular) | AS14: Nozzles (Toro) | AT14: Nozzles (MP) | AU14: 4" Heads (1804) | AV14: 4" Head PRS sams (1804) | AW14: 6" Heads (1806) | AX14: 12" Heads (1812) | AY14: Aircard | AZ14: Swing | BA14: Rotors (PGP Ultra) | BB14: Raise | BC14: Lower | BD14: Move | BE14: Add Spray Heads | BF14: Add Rotory Heads | BG14: Cap Heads | BH14: Mower Damage
A15: 26 | B15: Parking fornt of 125-137 docK | F15: X | G15: X | J15: B | K15: 20 | Z15: 1 | AE15: 1 | AP15: 1
A16: 27 | B16: Parking fornt of 125-137 docK | C16: X | G16: X | J16: C | K16: 10 | AE16: 1 | AP16: 1
A17: 28 | B17: Parking front 116-137 dock | E17: X | J17: B | K17: 5 | AE17: 1 | AK17: 1 | AP17: 1
A18: 29 | B18: Parking front 112-127 dock | C18: X | G18: X | J18: C | K18: 10 | AE18: 1 | AP18: 1
A19: 30 | B19: Parking front 101-111 dock | C19: X | G19: X | J19: C | K19: 10 | Z19: 1 | AE19: 1 | AP19: 1
A20: 31 | B20: Parking front | E20: X | J20: B | K20: 5 | AE20: 1 | AP20: 1
A21: 32
A22: 33
A23: 34
A24: 35
A25: 36
A26: 37
A27: 38
A28: 39
A29: 40
A30: 41
A31: 42
A32: 43
... A39: 50
Y40: =SUM(Y15:Y39) -> 0 | AC40: =SUM(AC15:AC39) -> 0 | AE40: 6 | AO40: =SUM(AO15:AO39) -> 0 | AP40: =SUM(AP15:AP39) -> 6 | BH40: =SUM(BH15:BH39) -> 0
B41: Notes:

Sheet club(1)-Comp
C9: 1814 W. Howard Ln. | K9: Phone: (512)266-3167
C10: Austin, TX 78728 | K10: Fax (512)266-7613
D13: Job Name: | F13: ='Controller B(2)'!G6 -> Amazon
D14: Job #: | F14: ='Controller B(2)'!G9 -> 0
D15: Inspection Date: | F15: ='Controller B(2)'!G10 -> 0
C18: Critical Repairs Needed
C20: QTY: | D20: Items: | E20: Cost Ea. | G20: Cost for Labor & Parts
C21: ='Controller B(2)'!R40 -> 0 | D21: Nozzles - Reg | E21: 2 | F21: =C21*E21 -> 0 | G21: + | H21: =SUM(80/I21)*C21 -> 0 | I21: 30 | J21: = | K21: =F21+H21 -> 0
C22: 29 | D22: Nozzles - Toro | E22: 4.25 | F22: =C22*E22 -> 123.25 | G22: + | H22: =SUM(80/I22)*C22 -> 77.333333 | I22: 30 | K22: =F22+H22 -> 200.58333
C23: ='Controller B(2)'!T40 -> 0 | D23: MP Nozzles | E23: 10 | F23: =C23*E23 -> 0 | G23: + | H23: =SUM(80/I23)*C23 -> 0 | I23: 12 | J23: = | K23: =F23+H23 -> 0
C24: 29 | D24: 4" Heads | E24: 4 | F24: =C24*E24 -> 116 | G24: + | H24: =SUM(80/I24)*C24 -> 331.42857 | I24: 7 | J24: = | K24: =F24+H24 -> 447.42857
C25: ='Controller B(2)'!V40 -> 0 | D25: 4" Head PRS Sams | E25: 8 | F25: =C25*E25 -> 0 | G25: + | H25: =SUM(80/I24)*C25 -> 0 | I25: 7 | J25: = | K25: =F25+H25 -> 0
C26: ='Controller B(2)'!W40 -> 0 | D26: 6" Heads | E26: 7 | F26: =C26*E26 -> 0 | G26: + | H26: =SUM(80/I26)*C26 -> 0 | I26: 6 | J26: = | K26: =F26+H26 -> 0
C27: ='Controller B(2)'!X40 -> 0 | D27: 12" Heads | E27: 15 | F27: =C27*E27 -> 0 | G27: + | H27: =SUM(80/I27)*C27 -> 0 | I27: 3 | J27: = | K27: =F27+H27 -> 0
C28: 118 | D28: Swing | E28: 3.5 | F28: =C28*E28 -> 413 | G28: + | H28: =SUM(80/I28)*C28 -> 1348.5714 | I28: 7 | J28: = | K28: =F28+H28 -> 1761.5714
C29: 16 | D29: Rotors | E29: 20 | F29: =C29*E29 -> 320 | G29: + | H29: =SUM(80/I29)*C29 -> 320 | I29: 4 | J29: = | K29: =F29+H29 -> 640
C30: 16 | D30: Drip Break | E30: 5.25 | F30: =C30*E30 -> 84 | G30: + | H30: =SUM(15*I30)*C30 -> 79.2 | I30: 0.33 | J30: = | K30: =F30+H30 -> 163.2
C31: 5 | D31: Line Break - Sm | E31: 34.5 | F31: =C31*E31 -> 172.5 | G31: + | H31: =SUM(80/I31)*C31 -> 200 | I31: 2 | J31: = | K31: =F31+H31 -> 372.5
C32: 15 | D32: Line Break - Lg | E32: 50 | F32: =C32*E32 -> 750 | G32: + | H32: =SUM(80/I32)*C32 -> 1200 | I32: 1 | K32: =F32+H32 -> 1950
C33: 8 | D33: 2" Valve | E33: 135 | F33: =C33*E33 -> 1080 | G33: + | H33: =SUM(80/I33)*C33 -> 1280 | I33: 0.5 | J33: = | K33: =F33+H33 -> 2360
C34: ='Controller B(2)'!AE40 -> 6 | D34: 1 ½" Valve | E34: 115 | F34: =C34*E34 -> 690 | G34: + | H34: =SUM(80/I34)*C34 -> 480 | I34: 1 | J34: = | K34: =F34+H34 -> 1170
C35: ='Controller B(2)'!AF40 -> 0 | D35: 1" Valve | E35: 75 | F35: =C35*E35 -> 0 | G35: + | H35: =SUM(80/I35)*C35 -> 0 | I35: 2 | J35: = | K35: =F35+H35 -> 0
C36: ='Controller B(2)'!AG40 -> 0 | D36: Decoder | E36: 138 | F36: =C36*E36 -> 0 | G36: + | H36: =SUM(80/I36)*C36 -> 0 | I36: 1 | J36: = | K36: =F36+H36 -> 0
C37: ='Controller B(2)'!AH40 -> 0 | D37: Solenoid | E37: 30 | F37: =C37*E37 -> 0 | G37: + | H37: =SUM(80/I37)*C37 -> 0 | I37: 2 | J37: = | K37: =F37+H37 -> 0
C38: ='Controller B(2)'!AI40 -> 0 | D38: Diaphragm | E38: 30 | F38: =C38*E38 -> 0 | G38: + | H38: =SUM(80/I38)*C38 -> 0 | I38: 2 | J38: = | K38: =F38+H38 -> 0
C39: ='Controller B(2)'!AJ40 -> 0 | D39: Main Line Leak | E39: 246 | F39: =C39*E39 -> 0 | G39: + | H39: =SUM(80/I39)*C39 -> 0 | I39: 0.5 | J39: = | K39: =F39+H39 -> 0
C40: ='Controller B(2)'!AK40 -> 0 | D40: 10" Valve Box Top | E40: 11.5 | F40: =C40*E40 -> 0 | G40: + | H40: =SUM(80/I40)*C40 -> 0 | I40: 30 | J40: = | K40: =F40+H40 -> 0
C41: ='Controller B(2)'!AL40 -> 0 | D41: 10" Valve Box | E41: 20 | F41: =C41*E41 -> 0 | G41: + | H41: =SUM(80/I41)*C41 -> 0 | I41: 30 | J41: = | K41: =F41+H41 -> 0
C42: ='Controller B(2)'!AM40 -> 0 | D42: 6" Valve Box Top | E42: 7.5 | F42: =C42*E42 -> 0 | G42: + | H42: =SUM(80/I42)*C42 -> 0 | I42: 30 | J42: = | K42: =F42+H42 -> 0
C43: ='Controller B(2)'!AN40 -> 0 | D43: 6" Valve Box | E43: 10 | F43: =C43*E43 -> 0 | G43: + | H43: =SUM(80/I43)*C43 -> 0 | I43: 30 | J43: = | K43: =F43+H43 -> 0
C44: 107 | D44: Bubblers | E44: 5.75 | F44: =C44*E44 -> 615.25 | G44: + | H44: =SUM(80/I44)*C44 -> 1426.6667 | I44: 6 | J44: = | K44: =F44+H44 -> 2041.9167
C45: 20 | D45: Cut wires | E45: 115 | F45: =C45*E45 -> 2300 | G45: + | H45: =SUM(80*I45)*C45 -> 800 | I45: 0.5 | J45: = | K45: =F45+H45 -> 3100
C46: 1 | D46: Add A Zone | E46: 125 | F46: =C46*E46 -> 125 | G46: + | H46: =SUM(80/I46)*C46 -> 80 | I46: 1 | J46: = | K46: =F46+H46 -> 205
J47: TOTAL | K47: =SUM(K21:K46) -> 14412.2
C49: Non-Critical Repairs Needed
C51: QTY: | D51: Items: | G51: Cost for Labor & Parts
C52: ='Controller B(2)'!AR40 -> 0 | D52: Nozzles - Reg | E52: 2 | F52: =C52*E52 -> 0 | G52: + | H52: =SUM(80/I52)*C52 -> 0 | I52: 30 | J52: = | K52: =F52+H52 -> 0
C53: ='Controller B(2)'!AS40 -> 0 | D53: Nozzles - Toro | E53: 4.25 | F53: =C53*E53 -> 0 | G53: + | H53: =SUM(80/I53)*C53 -> 0 | I53: 30 | K53: =F53+H53 -> 0
C54: ='Controller B(2)'!AT40 -> 0 | D54: MP Nozzles | E54: 10 | F54: =C54*E54 -> 0 | G54: + | H54: =SUM(80/I54)*C54 -> 0 | I54: 12 | J54: = | K54: =F54+H54 -> 0
C55: ='Controller B(2)'!AU40 -> 0 | D55: 4" Heads | E55: 4 | F55: =C55*E55 -> 0 | G55: + | H55: =SUM(80/I55)*C55 -> 0 | I55: 7 | J55: = | K55: =F55+H55 -> 0
...

Sheet club(2)-Comp
C9: 1814 W. Howard Ln. | K9: Phone: (512)266-3167
C10: Austin, TX 78728 | K10: Fax (512)266-7613
D13: Job Name: | F13: ='Controller A (3)'!G6 -> Amazon
D14: Job #: | F14: ='Controller A (3)'!G9 -> 0
D15: Inspection Date: | F15: ='Controller A (3)'!G10 -> 9.25.2024
C18: Critical Repairs Needed
C20: QTY: | D20: Items: | E20: Cost Ea. | G20: Cost for Labor & Parts
C21: ='Controller A (3)'!R40 -> 7 | D21: Nozzles - Reg | E21: 2 | F21: =C21*E21 -> 14 | G21: + | H21: =SUM(80/I21)*C21 -> 18.666667 | I21: 30 | J21: = | K21: =F21+H21 -> 32.666667
C22: ='Controller A (3)'!S40 -> 0 | D22: Nozzles - Toro | E22: 4.25 | F22: =C22*E22 -> 0 | G22: + | H22: =SUM(80/I22)*C22 -> 0 | I22: 30 | K22: =F22+H22 -> 0
C23: ='Controller A (3)'!T40 -> 0 | D23: MP Nozzles | E23: 10 | F23: =C23*E23 -> 0 | G23: + | H23: =SUM(80/I23)*C23 -> 0 | I23: 12 | J23: = | K23: =F23+H23 -> 0
C24: ='Controller A (3)'!U40 -> 5 | D24: 4" Heads | E24: 4 | F24: =C24*E24 -> 20 | G24: + | H24: =SUM(80/I24)*C24 -> 57.142857 | I24: 7 | J24: = | K24: =F24+H24 -> 77.142857
C25: ='Controller A (3)'!V40 -> 0 | D25: 4" Head PRS Sams | E25: 8 | F25: =C25*E25 -> 0 | G25: + | H25: =SUM(80/I24)*C25 -> 0 | I25: 7 | J25: = | K25: =F25+H25 -> 0
C26: ='Controller A (3)'!W40 -> 0 | D26: 6" Heads | E26: 7 | F26: =C26*E26 -> 0 | G26: + | H26: =SUM(80/I26)*C26 -> 0 | I26: 6 | J26: = | K26: =F26+H26 -> 0
C27: ='Controller A (3)'!X40 -> 0 | D27: 12" Heads | E27: 15 | F27: =C27*E27 -> 0 | G27: + | H27: =SUM(80/I27)*C27 -> 0 | I27: 3 | J27: = | K27: =F27+H27 -> 0
C28: ='Controller A (3)'!Y40 -> 0 | D28: Swing | E28: 3.5 | F28: =C28*E28 -> 0 | G28: + | H28: =SUM(80/I28)*C28 -> 0 | I28: 7 | J28: = | K28: =F28+H28 -> 0
C29: ='Controller A (3)'!Z40 -> 5 | D29: Rotors | E29: 20 | F29: =C29*E29 -> 100 | G29: + | H29: =SUM(80/I29)*C29 -> 100 | I29: 4 | J29: = | K29: =F29+H29 -> 200
C30: ='Controller A (3)'!AA40 -> 0 | D30: Drip Break | E30: 5.25 | F30: =C30*E30 -> 0 | G30: + | H30: =SUM(15*I30)*C30 -> 0 | I30: 0.33 | J30: = | K30: =F30+H30 -> 0
C31: ='Controller A (3)'!AB40 -> 1 | D31: Line Break - Sm | E31: 34.5 | F31: =C31*E31 -> 34.5 | G31: + | H31: =SUM(80/I31)*C31 -> 40 | I31: 2 | J31: = | K31: =F31+H31 -> 74.5
C32: ='Controller A (3)'!AC40 -> 3 | D32: Line Break - Lg | E32: 50 | F32: =C32*E32 -> 150 | G32: + | H32: =SUM(80/I32)*C32 -> 240 | I32: 1 | K32: =F32+H32 -> 390
C33: ='Controller A (3)'!AD40 -> 0 | D33: 2" Valve | E33: 135 | F33: =C33*E33 -> 0 | G33: + | H33: =SUM(80/I33)*C33 -> 0 | I33: 0.5 | J33: = | K33: =F33+H33 -> 0
C34: ='Controller A (3)'!AE40 -> 0 | D34: 1 ½" Valve | E34: 115 | F34: =C34*E34 -> 0 | G34: + | H34: =SUM(80/I34)*C34 -> 0 | I34: 1 | J34: = | K34: =F34+H34 -> 0
C35: ='Controller A (3)'!AF40 -> 0 | D35: 1" Valve | E35: 75 | F35: =C35*E35 -> 0 | G35: + | H35: =SUM(80/I35)*C35 -> 0 | I35: 2 | J35: = | K35: =F35+H35 -> 0
C36: ='Controller A (3)'!AG40 -> 0 | D36: Decoder | E36: 138 | F36: =C36*E36 -> 0 | G36: + | H36: =SUM(80/I36)*C36 -> 0 | I36: 1 | J36: = | K36: =F36+H36 -> 0
C37: ='Controller A (3)'!AH40 -> 0 | D37: Solenoid | E37: 30 | F37: =C37*E37 -> 0 | G37: + | H37: =SUM(80/I37)*C37 -> 0 | I37: 2 | J37: = | K37: =F37+H37 -> 0
C38: ='Controller A (3)'!AI40 -> 0 | D38: Diaphragm | E38: 30 | F38: =C38*E38 -> 0 | G38: + | H38: =SUM(80/I38)*C38 -> 0 | I38: 2 | J38: = | K38: =F38+H38 -> 0
C39: ='Controller A (3)'!AJ40 -> 2 | D39: Main Line Leak | E39: 246 | F39: =C39*E39 -> 492 | G39: + | H39: =SUM(80/I39)*C39 -> 320 | I39: 0.5 | J39: = | K39: =F39+H39 -> 812
C40: ='Controller A (3)'!AK40 -> 0 | D40: 10" Valve Box Top | E40: 11.5 | F40: =C40*E40 -> 0 | G40: + | H40: =SUM(80/I40)*C40 -> 0 | I40: 30 | J40: = | K40: =F40+H40 -> 0
C41: ='Controller A (3)'!AL40 -> 0 | D41: 10" Valve Box | E41: 20 | F41: =C41*E41 -> 0 | G41: + | H41: =SUM(80/I41)*C41 -> 0 | I41: 30 | J41: = | K41: =F41+H41 -> 0
C42: ='Controller A (3)'!AM40 -> 0 | D42: 6" Valve Box Top | E42: 7.5 | F42: =C42*E42 -> 0 | G42: + | H42: =SUM(80/I42)*C42 -> 0 | I42: 30 | J42: = | K42: =F42+H42 -> 0
C43: ='Controller A (3)'!AN40 -> 0 | D43: 6" Valve Box | E43: 10 | F43: =C43*E43 -> 0 | G43: + | H43: =SUM(80/I43)*C43 -> 0 | I43: 30 | J43: = | K43: =F43+H43 -> 0
C44: ='Controller A (3)'!AO40 -> 2 | D44: Bubblers | E44: 5.75 | F44: =C44*E44 -> 11.5 | G44: + | H44: =SUM(80/I44)*C44 -> 26.666667 | I44: 6 | J44: = | K44: =F44+H44 -> 38.166667
C45: ='Controller A (3)'!AP40 -> 0 | D45: Cut wires | E45: 115 | F45: =C45*E45 -> 0 | G45: + | H45: =SUM(80*I45)*C45 -> 0 | I45: 0.5 | J45: = | K45: =F45+H45 -> 0
C46: ='Controller A (3)'!AQ40 -> 3 | D46: Add A Zone | E46: 125 | F46: =C46*E46 -> 375 | G46: + | H46: =SUM(80/I46)*C46 -> 240 | I46: 1 | J46: = | K46: =F46+H46 -> 615
J47: TOTAL | K47: =SUM(K21:K46) -> 2239.4762
C49: Non-Critical Repairs Needed
C51: QTY: | D51: Items: | G51: Cost for Labor & Parts
C52: ='Controller A (3)'!AR40 -> 0 | D52: Nozzles - Reg | E52: 2 | F52: =C52*E52 -> 0 | G52: + | H52: =SUM(80/I52)*C52 -> 0 | I52: 30 | J52: = | K52: =F52+H52 -> 0
C53: ='Controller A (3)'!AS40 -> 0 | D53: Nozzles - Toro | E53: 4.25 | F53: =C53*E53 -> 0 | G53: + | H53: =SUM(80/I53)*C53 -> 0 | I53: 30 | K53: =F53+H53 -> 0
C54: ='Controller A (3)'!AT40 -> 0 | D54: MP Nozzles | E54: 10 | F54: =C54*E54 -> 0 | G54: + | H54: =SUM(80/I54)*C54 -> 0 | I54: 12 | J54: = | K54: =F54+H54 -> 0
C55: ='Controller A (3)'!AU40 -> 0 | D55: 4" Heads | E55: 4 | F55: =C55*E55 -> 0 | G55: + | H55: =SUM(80/I55)*C55 -> 0 | I55: 7 | J55: = | K55: =F55+H55 -> 0
...

Sheet Mod
C9: 1814 W. Howard Ln. | K9: Phone: (512)266-3167
C10: Austin, TX 78728 | K10: Fax (512)266-7613
D13: Job Name: | F13: =Cover!A8 -> Amazon
D14: Job #: | F14: =Cover!K9 -> 0
D15: Inspection Date: | F15: =Cover!I14 -> 9.25.2024
C18: Modifications
C19: QTY: | D19: Items: | G19: Cost for Labor & Parts
D20: RPZ Device 2" | E20: 650 | F20: =+E20*C20 -> 0 | G20: + | H20: 80 | I20: =SUM(C20*80*4) -> 0 | J20: = | K20: =F20+I20 -> 0
D21: Convert to Drip | E21: 721.74 | F21: 0 | G21: + | H21: 80 | I21: =SUM(C21*80*4) -> 0 | J21: = | K21: =F21+I21 -> 0
D22: PRV device 1" | E22: 250 | F22: =+E22*C22 -> 0 | G22: + | H22: 80 | I22: =SUM(C22*80*2) -> 0 | J22: = | K22: =F22+I22 -> 0
D23: Dbl check 1" | E23: 299.46 | F23: =+E23*C23 -> 0 | G23: + | H23: 80 | I23: =SUM(C23*80*2) -> 0 | J23: = | K23: =F23+I23 -> 0
D24: Jumbo Pl Meter BX | E24: 76.8775 | F24: =+E24*C24 -> 0 | G24: + | H24: 80 | I24: =SUM(C24*80*2) -> 0 | J24: = | K24: =F24+I24 -> 0
D25: Standard Pl Meter Bx | E25: 36.9725 | F25: =+E25*C25 -> 0 | G25: + | H25: 80 | I25: =SUM(C25*80*2) -> 0 | J25: = | K25: =F25+I25 -> 0
D26: DCA 2" | E26: 550 | F26: =+E26*C26 -> 0 | G26: + | H26: 80 | I26: =SUM(C26*80*4) -> 0 | J26: = | K26: =F26+I26 -> 0
D27: Pressure Reg 2" | E27: 617.55 | F27: =+E27*C27 -> 0 | G27: + | H27: 80 | I27: =SUM(C27*80*2) -> 0 | J27: = | K27: =F27+I27 -> 0
D28: 1" Y Strainer | E28: 172.5 | F28: =+E28*C28 -> 0 | G28: + | H28: 80 | I28: =SUM(C28*80*1.5) -> 0 | J28: = | K28: =F28+I28 -> 0
D29: 2" Y Strainer | E29: 212.75 | F29: =+E29*C29 -> 0 | G29: + | H29: 80 | I29: =SUM(C29*80*2.5) -> 0 | J29: = | K29: =F29+I29 -> 0
D30: Inspection | E30: 150 | F30: =+E30*C30 -> 0 | G30: + | H30: 0 | J30: = | K30: =F30+I30 -> 0
J31: TOTAL COST: | K31: =SUM(K20:K30) -> 0
C33: Controllers:
D34: Hunter Pro C (4) | E34: 300 | F34: =SUM(E34)*C34 -> 0 | G34: + | H34: 80 | I34: =SUM(C34)*80*2 -> 0 | J34: = | K34: =SUM(F34)+I34 -> 0
D35: Hunter Pro C (10) | E35: 400 | F35: =SUM(E35)*C35 -> 0 | G35: + | H35: 80 | I35: =SUM(C35)*80*2 -> 0 | J35: = | K35: =SUM(F35)+I35 -> 0
D36: Hunter Pro C (15) | E36: 500 | F36: =SUM(E36)*C36 -> 0 | G36: + | H36: 80 | I36: =SUM(C36)*80*2 -> 0 | J36: = | K36: =SUM(F36)+I36 -> 0
D37: Hunter I-Core (10) | E37: 650 | F37: =SUM(E37)*C37 -> 0 | G37: + | H37: 80 | I37: =SUM(C37)*80*2 -> 0 | J37: = | K37: =SUM(F37)+I37 -> 0
D38: Hunter I-Core (15) | E38: 850 | F38: =SUM(E38)*C38 -> 0 | G38: + | H38: 80 | I38: =SUM(C38)*80*2 -> 0 | J38: = | K38: =SUM(F38)+I38 -> 0
D39: Hunter I-Core (24) | E39: 950 | F39: =SUM(E39)*C39 -> 0 | G39: + | H39: 80 | I39: =SUM(C39)*80*2 -> 0 | J39: = | K39: =SUM(F39)+I39 -> 0
D40: Hunter I-Core (32) | E40: 1225 | F40: =SUM(E40)*C40 -> 0 | G40: + | H40: 80 | I40: =SUM(C40)*80*2 -> 0 | J40: = | K40: =SUM(F40)+I40 -> 0
D41: Hunter I-Core (42) | E41: 1177.61 | F41: =SUM(E41)*C41 -> 0 | G41: + | H41: 80 | I41: =SUM(C41)*80*2 -> 0 | J41: = | K41: =SUM(F41)+I41 -> 0
D42: Weathermatic/Aircard (4) | E42: 650 | F42: =SUM(E42)*C42 -> 0 | G42: + | H42: 80 | I42: =SUM(C42)*80*2 -> 0 | J42: = | K42: =SUM(F42)+I42 -> 0
D43: Weathermatic/Aircard (12) | E43: 850 | F43: =SUM(E43)*C43 -> 0 | G43: + | H43: 80 | I43: =SUM(C43)*80*2 -> 0 | J43: = | K43: =SUM(F43)+I43 -> 0
D44: Weathermatic/Aircard (15) | E44: 925 | F44: =SUM(E44)*C44 -> 0 | G44: + | H44: 80 | I44: =SUM(C44)*80*2 -> 0 | J44: = | K44: =SUM(F44)+I44 -> 0
D45: Weathermatic/Aircard (24) | E45: 1150 | F45: =SUM(E45)*C45 -> 0 | G45: + | H45: 80 | I45: =SUM(C45)*80*2 -> 0 | J45: = | K45: =SUM(F45)+I45 -> 0
... D51: Weathermatic (48) | E51: 1205 | F51: =SUM(E51)*C51 -> 0 | G51: + | H51: 80 | I51: =SUM(C51)*80*2 -> 0 | J51: = | K51: =SUM(F51)+I51 -> 0
D52: SVC 1 Station | E52: 120 | F52: =SUM(E52)*C52 -> 0 | G52: + | H52: 80 | I52: =SUM(C52)*80*1 -> 0 | J52: = | K52: =SUM(F52)+I52 -> 0
J53: TOTAL COST: | K53: =SUM(K34:K52) -> 0
C55: Rain/Freeze Sensors:
D56: Hunter/Rainbird Wireless | E56: 170 | F56: =+(E56)*C56 -> 0 | G56: + | H56: 80 | I56: =SUM(C56*80*1) -> 0 | J56: = | K56: =SUM(F56)+I56 -> 0
D57: Weather Station (WM) | E57: 250 | F57: =+(E57)*C57 -> 0 | G57: + | H57: 80 | I57: =SUM(C57*80*1) -> 0 | J57: = | K57: =SUM(F57)+I57 -> 0
J58: TOTAL COST: | K58: =SUM(K56:K57) -> 0
C63: **(PLEASE NOTE: ALL TOTALS GIVEN DO NOT INCLUDE SALES TAX)**
